Workbook
Name _FilterDatabase_0: 'BASE DE DADOS'!$P$1:$R$122
Name _FilterDatabase_0_0: 'BASE DE DADOS'!$P$1:$R$122

Sheet DADOS
A1: CLIENTES | B1: CLASSE | C1: DEMANDA
A2: 1 | B2: CLASSE "A" | C2: 1
A3: 1 | B3: CLASSE "B" | C3: 1.6
A4: 1 | B4: CLASSE "C" | C4: 2.6
A5: 1 | B5: CLASSE "D" | C5: 4
A6: 2 | B6: CLASSE "A" | C6: 1
A7: 2 | B7: CLASSE "B" | C7: 1.6
A8: 2 | B8: CLASSE "C" | C8: 2.6
A9: 2 | B9: CLASSE "D" | C9: 4
A10: 3 | B10: CLASSE "A" | C10: 1
A11: 3 | B11: CLASSE "B" | C11: 1.6
A12: 3 | B12: CLASSE "C" | C12: 2.6
A13: 3 | B13: CLASSE "D" | C13: 4
... A481: 120 | B481: CLASSE "D" | C481: 2

Sheet ATUAL
J1: TRECHO | K1: TOTAL | L1: MONO | M1: BI | N1: TRI | O1: TRI ESPECIAL | R1: TOTAL | S1: IP70W | T1: IP80W | U1: IP150W | V1: IP250W | W1: IP400W
A2: DEMANDA DIVERSIFICADA EM KVA | F2: LUMIN. | G2: QUANT | H2: DEMANDA | O2: QUANT | P2: CARGA
A3: TIPO DE LIGAÇÃO | C3: CLASSE "B" | F3: IP70W | G3: =SUM(S3:S57) -> 0 | H3: 0.07 | J3: TRAFO | K3: =SUM(L3:N3)*$C$5+P3 -> 75 | O3: 1 | P3: 75 | R3: =S3*$H$3+T3*$H$4+U3*$H$5+V3*$H$6+W3*$H$7 -> 0
A4: TOTAL DE CLIENTES | C4: =SUM(L3:O57) -> 4 | F4: IP80W | G4: =SUM(T3:T57) -> 0 | H4: 0.08 | J4: 2 | K4: =SUM(L4:N4)*$C$5+P4 -> 0 | R4: =S4*$H$3+T4*$H$4+U4*$H$5+V4*$H$6+W4*$H$7 -> 0
A5: DEMANDA UNITÁRIA | C5: 1.6 | F5: IP150W | G5: =SUM(U3:U57) -> 0 | H5: 0.15 | J5: 3 | K5: =SUM(L5:N5)*$C$5+P5 -> 0 | R5: =S5*$H$3+T5*$H$4+U5*$H$5+V5*$H$6+W5*$H$7 -> 0
D6: =SUM(L3:N15)*C5 -> 4.8 | F6: IP250W | G6: =SUM(V3:V57) -> 0 | H6: 0.25 | J6: 4 | K6: =SUM(L6:N6)*$C$5+P6 -> 0 | R6: =S6*$H$3+T6*$H$4+U6*$H$5+V6*$H$6+W6*$H$7 -> 0
C7: =D6+D7 -> 79.8 | D7: =P3 -> 75 | F7: IP400W | G7: =SUM(W3:W57) -> 0 | H7: 0.4 | J7: 5 | K7: =SUM(L7:N7)*$C$5+P7 -> 1.6 | N7: 1 | R7: =S7*$H$3+T7*$H$4+U7*$H$5+V7*$H$6+W7*$H$7 -> 0
J8: 6 | K8: =SUM(L8:N8)*$C$5+P8 -> 3.2 | L8: 1 | N8: 1 | R8: =S8*$H$3+T8*$H$4+U8*$H$5+V8*$H$6+W8*$H$7 -> 0
J9: 7 | K9: =SUM(L9:N9)*$C$5+P9 -> 0 | R9: =S9*$H$3+T9*$H$4+U9*$H$5+V9*$H$6+W9*$H$7 -> 0
J10: 8 | K10: =SUM(L10:N10)*$C$5+P10 -> 0 | R10: =S10*$H$3+T10*$H$4+U10*$H$5+V10*$H$6+W10*$H$7 -> 0
J11: 9 | K11: =SUM(L11:N11)*$C$5+P11 -> 0 | R11: =S11*$H$3+T11*$H$4+U11*$H$5+V11*$H$6+W11*$H$7 -> 0
J12: 10 | K12: =SUM(L12:N12)*$C$5+P12 -> 0 | R12: =S12*$H$3+T12*$H$4+U12*$H$5+V12*$H$6+W12*$H$7 -> 0
J13: 11 | K13: =SUM(L13:N13)*$C$5+P13 -> 0 | R13: =S13*$H$3+T13*$H$4+U13*$H$5+V13*$H$6+W13*$H$7 -> 0
J14: 12 | K14: =SUM(L14:N14)*$C$5+P14 -> 0 | R14: =S14*$H$3+T14*$H$4+U14*$H$5+V14*$H$6+W14*$H$7 -> 0
J15: 13 | K15: =SUM(L15:N15)*$C$5+P15 -> 0 | R15: =S15*$H$3+T15*$H$4+U15*$H$5+V15*$H$6+W15*$H$7 -> 0
J16: 14 | K16: =SUM(L16:N16)*$C$5+P16 -> 0 | R16: =S16*$H$3+T16*$H$4+U16*$H$5+V16*$H$6+W16*$H$7 -> 0
J17: 15 | K17: =SUM(L17:N17)*$C$5+P17 -> 0 | R17: =S17*$H$3+T17*$H$4+U17*$H$5+V17*$H$6+W17*$H$7 -> 0
J18: 16 | K18: =SUM(L18:N18)*$C$5+P18 -> 0 | R18: =S18*$H$3+T18*$H$4+U18*$H$5+V18*$H$6+W18*$H$7 -> 0
J19: 17 | K19: =SUM(L19:N19)*$C$5+P19 -> 0 | R19: =S19*$H$3+T19*$H$4+U19*$H$5+V19*$H$6+W19*$H$7 -> 0
J20: 18 | K20: =SUM(L20:N20)*$C$5+P20 -> 0 | R20: =S20*$H$3+T20*$H$4+U20*$H$5+V20*$H$6+W20*$H$7 -> 0
... J57: 55 | K57: =SUM(L57:N57)*$C$5+P57 -> 0 | R57: =S57*$H$3+T57*$H$4+U57*$H$5+V57*$H$6+W57*$H$7 -> 0

Sheet CQT ATUAL
A1: PROJETO | B1: A052750522 | G1: CARREGAMENTO TRANSFORMADOR
A3: SUBESTAÇÃO | B3: SANTA CLARA | D3: POTÊNCIA DO TRANSFORMADOR - kVA | F3: 75 | G3: =(F5)/F3 -> 1.064
A4: TAXA DE CRESCIMENTO ANUAL | B4: =VLOOKUP(B3,'BASE DE DADOS'!P:R,2,0) -> 0.035 | D4: PONTO ELÉTRICO DO TRANSFORMADOR | F4: C380653
A5: FATOR MULTIPLICATIVO 5 ANOS | B5: 1 | D5: DEMANDA TOTAL DO CIRCUITO DE BT - kVA | F5: =SUM(ATUAL!K3:K57)+SUM(ATUAL!R3:R57) -> 79.8
A7: TRECHOS | D7: CARGAS | I7: CONDUTOR | J7: QUEDA DE TENSÃO
A8: TRECHO | B8: TRECHO MONTANTE | C8: COMPRIMENTO | D8: DISTRIBUÍDA NO TRECHO | G8: ACUMULADA NO FINAL DO TRECHO | H8: TOTAL (C/2+D)*B | J8: UNITÁRIO | K8: NO TRECHO | L8: TOTAL
A9: A | C9: B - 100 | D9: C - kVA | G9: D - kVA | H9: E - kVA x B | I9: F - mm² | J9: G - % | K9: H - % | L9: I - %
A10: TRAFO | D10: CLIENTES | E10: ILUMINAÇÃO PÚBLICA | F10: TOTAL DO TRECHO
A11: 2 | B11: TRAFO | C11: 0.35 | D11: =ATUAL!K4 -> 0 | E11: =ATUAL!R4 -> 0 | F11: =D11+E11 -> 0 | G11: =SUMIF($B$11:$B$64,A11,$G$11:$G$64)+F11 -> 4.8 | H11: =(G11-(D11/2))*C11 -> 1.68 | I11: 3x50+1x50 - Al - F.P 1 | J11: =IFERROR(VLOOKUP(I11,'BASE DE DADOS'!$A$4:$B$83,2,0)," ") -> 0.1784 | K11: =IFERROR(H11*J11," ") -> 0.299712 | L11: =IFERROR(IF(B11="TRAFO",K11,SUMIFS($L$11:$L$64,$A$11:$A$64,B11)+K11)," ") -> 0.299712
A12: 3 | B12: 2 | C12: 0.12 | D12: =ATUAL!K5 -> 0 | E12: =ATUAL!R5 -> 0 | F12: =D12+E12 -> 0 | G12: =SUMIF($B$11:$B$64,A12,$G$11:$G$64)+F12 -> 4.8 | H12: =(G12-(D12/2))*C12 -> 0.576 | I12: 3x50+1x50 - Al - F.P 1 | J12: =IFERROR(VLOOKUP(I12,'BASE DE DADOS'!$A$4:$B$83,2,0)," ") -> 0.1784 | K12: =IFERROR(H12*J12," ") -> 0.1027584 | L12: =IFERROR(IF(B12="TRAFO",K12,SUMIFS($L$11:$L$64,$A$11:$A$64,B12)+K12)," ") -> 0.4024704
A13: 4 | B13: 3 | C13: 0.4 | D13: =ATUAL!K6 -> 0 | E13: =ATUAL!R6 -> 0 | F13: =D13+E13 -> 0 | G13: =SUMIF($B$11:$B$64,A13,$G$11:$G$64)+F13 -> 4.8 | H13: =(G13-(D13/2))*C13 -> 1.92 | I13: 3x50+1x50 - Al - F.P 1 | J13: =IFERROR(VLOOKUP(I13,'BASE DE DADOS'!$A$4:$B$83,2,0)," ") -> 0.1784 | K13: =IFERROR(H13*J13," ") -> 0.342528 | L13: =IFERROR(IF(B13="TRAFO",K13,SUMIFS($L$11:$L$64,$A$11:$A$64,B13)+K13)," ") -> 0.7449984
A14: 5 | B14: 4 | C14: 0.4 | D14: =ATUAL!K7 -> 1.6 | E14: =ATUAL!R7 -> 0 | F14: =D14+E14 -> 1.6 | G14: =SUMIF($B$11:$B$64,A14,$G$11:$G$64)+F14 -> 4.8 | H14: =(G14-(D14/2))*C14 -> 1.6 | I14: 3x50+1x50 - Al - F.P 1 | J14: =IFERROR(VLOOKUP(I14,'BASE DE DADOS'!$A$4:$B$83,2,0)," ") -> 0.1784 | K14: =IFERROR(H14*J14," ") -> 0.28544 | L14: =IFERROR(IF(B14="TRAFO",K14,SUMIFS($L$11:$L$64,$A$11:$A$64,B14)+K14)," ") -> 1.0304384
A15: 6 | B15: 5 | C15: 0.4 | D15: =ATUAL!K8 -> 3.2 | E15: =ATUAL!R8 -> 0 | F15: =D15+E15 -> 3.2 | G15: =SUMIF($B$11:$B$64,A15,$G$11:$G$64)+F15 -> 3.2 | H15: =(G15-(D15/2))*C15 -> 0.64 | I15: 3x50+1x50 - Al - F.P 1 | J15: =IFERROR(VLOOKUP(I15,'BASE DE DADOS'!$A$4:$B$83,2,0)," ") -> 0.1784 | K15: =IFERROR(H15*J15," ") -> 0.114176 | L15: =IFERROR(IF(B15="TRAFO",K15,SUMIFS($L$11:$L$64,$A$11:$A$64,B15)+K15)," ") -> 1.1446144
A16: 7 | D16: =ATUAL!K9 -> 0 | E16: =ATUAL!R9 -> 0 | F16: =D16+E16 -> 0 | G16: =SUMIF($B$11:$B$64,A16,$G$11:$G$64)+F16 -> 0 | H16: =(G16-(D16/2))*C16 -> 0 | J16: =IFERROR(VLOOKUP(I16,'BASE DE DADOS'!$A$4:$B$83,2,0)," ") | K16: =IFERROR(H16*J16," ") | L16: =IFERROR(IF(B16="TRAFO",K16,SUMIFS($L$11:$L$64,$A$11:$A$64,B16)+K16)," ")
A17: 8 | D17: =ATUAL!K10 -> 0 | E17: =ATUAL!R10 -> 0 | F17: =D17+E17 -> 0 | G17: =SUMIF($B$11:$B$64,A17,$G$11:$G$64)+F17 -> 0 | H17: =(G17-(D17/2))*C17 -> 0 | J17: =IFERROR(VLOOKUP(I17,'BASE DE DADOS'!$A$4:$B$83,2,0)," ") | K17: =IFERROR(H17*J17," ") | L17: =IFERROR(IF(B17="TRAFO",K17,SUMIFS($L$11:$L$64,$A$11:$A$64,B17)+K17)," ")
A18: 9 | D18: =ATUAL!K11 -> 0 | E18: =ATUAL!R11 -> 0 | F18: =D18+E18 -> 0 | G18: =SUMIF($B$11:$B$64,A18,$G$11:$G$64)+F18 -> 0 | H18: =(G18-(D18/2))*C18 -> 0 | J18: =IFERROR(VLOOKUP(I18,'BASE DE DADOS'!$A$4:$B$83,2,0)," ") | K18: =IFERROR(H18*J18," ") | L18: =IFERROR(IF(B18="TRAFO",K18,SUMIFS($L$11:$L$64,$A$11:$A$64,B18)+K18)," ")
A19: 10 | D19: =ATUAL!K12 -> 0 | E19: =ATUAL!R12 -> 0 | F19: =D19+E19 -> 0 | G19: =SUMIF($B$11:$B$64,A19,$G$11:$G$64)+F19 -> 0 | H19: =(G19-(D19/2))*C19 -> 0 | J19: =IFERROR(VLOOKUP(I19,'BASE DE DADOS'!$A$4:$B$83,2,0)," ") | K19: =IFERROR(H19*J19," ") | L19: =IFERROR(IF(B19="TRAFO",K19,SUMIFS($L$11:$L$64,$A$11:$A$64,B19)+K19)," ")
A20: 11 | D20: =ATUAL!K13 -> 0 | E20: =ATUAL!R13 -> 0 | F20: =D20+E20 -> 0 | G20: =SUMIF($B$11:$B$64,A20,$G$11:$G$64)+F20 -> 0 | H20: =(G20-(D20/2))*C20 -> 0 | J20: =IFERROR(VLOOKUP(I20,'BASE DE DADOS'!$A$4:$B$83,2,0)," ") | K20: =IFERROR(H20*J20," ") | L20: =IFERROR(IF(B20="TRAFO",K20,SUMIFS($L$11:$L$64,$A$11:$A$64,B20)+K20)," ")
A21: 12 | D21: =ATUAL!K14 -> 0 | E21: =ATUAL!R14 -> 0 | F21: =D21+E21 -> 0 | G21: =SUMIF($B$11:$B$64,A21,$G$11:$G$64)+F21 -> 0 | H21: =(G21-(D21/2))*C21 -> 0 | J21: =IFERROR(VLOOKUP(I21,'BASE DE DADOS'!$A$4:$B$83,2,0)," ") | K21: =IFERROR(H21*J21," ") | L21: =IFERROR(IF(B21="TRAFO",K21,SUMIFS($L$11:$L$64,$A$11:$A$64,B21)+K21)," ")
A22: 13 | D22: =ATUAL!K15 -> 0 | E22: =ATUAL!R15 -> 0 | F22: =D22+E22 -> 0 | G22: =SUMIF($B$11:$B$64,A22,$G$11:$G$64)+F22 -> 0 | H22: =(G22-(D22/2))*C22 -> 0 | J22: =IFERROR(VLOOKUP(I22,'BASE DE DADOS'!$A$4:$B$83,2,0)," ") | K22: =IFERROR(H22*J22," ") | L22: =IFERROR(IF(B22="TRAFO",K22,SUMIFS($L$11:$L$64,$A$11:$A$64,B22)+K22)," ")
A23: 14 | D23: =ATUAL!K16 -> 0 | E23: =ATUAL!R16 -> 0 | F23: =D23+E23 -> 0 | G23: =SUMIF($B$11:$B$64,A23,$G$11:$G$64)+F23 -> 0 | H23: =(G23-(D23/2))*C23 -> 0 | J23: =IFERROR(VLOOKUP(I23,'BASE DE DADOS'!$A$4:$B$83,2,0)," ") | K23: =IFERROR(H23*J23," ") | L23: =IFERROR(IF(B23="TRAFO",K23,SUMIFS($L$11:$L$64,$A$11:$A$64,B23)+K23)," ")
A24: 15 | D24: =ATUAL!K17 -> 0 | E24: =ATUAL!R17 -> 0 | F24: =D24+E24 -> 0 | G24: =SUMIF($B$11:$B$64,A24,$G$11:$G$64)+F24 -> 0 | H24: =(G24-(D24/2))*C24 -> 0 | J24: =IFERROR(VLOOKUP(I24,'BASE DE DADOS'!$A$4:$B$83,2,0)," ") | K24: =IFERROR(H24*J24," ") | L24: =IFERROR(IF(B24="TRAFO",K24,SUMIFS($L$11:$L$64,$A$11:$A$64,B24)+K24)," ")
A25: 16 | D25: =ATUAL!K18 -> 0 | E25: =ATUAL!R18 -> 0 | F25: =D25+E25 -> 0 | G25: =SUMIF($B$11:$B$64,A25,$G$11:$G$64)+F25 -> 0 | H25: =(G25-(D25/2))*C25 -> 0 | J25: =IFERROR(VLOOKUP(I25,'BASE DE DADOS'!$A$4:$B$83,2,0)," ") | K25: =IFERROR(H25*J25," ") | L25: =IFERROR(IF(B25="TRAFO",K25,SUMIFS($L$11:$L$64,$A$11:$A$64,B25)+K25)," ")
A26: 17 | D26: =ATUAL!K19 -> 0 | E26: =ATUAL!R19 -> 0 | F26: =D26+E26 -> 0 | G26: =SUMIF($B$11:$B$64,A26,$G$11:$G$64)+F26 -> 0 | H26: =(G26-(D26/2))*C26 -> 0 | J26: =IFERROR(VLOOKUP(I26,'BASE DE DADOS'!$A$4:$B$83,2,0)," ") | K26: =IFERROR(H26*J26," ") | L26: =IFERROR(IF(B26="TRAFO",K26,SUMIFS($L$11:$L$64,$A$11:$A$64,B26)+K26)," ")
A27: 18 | D27: =ATUAL!K20 -> 0 | E27: =ATUAL!R20 -> 0 | F27: =D27+E27 -> 0 | G27: =SUMIF($B$11:$B$64,A27,$G$11:$G$64)+F27 -> 0 | H27: =(G27-(D27/2))*C27 -> 0 | J27: =IFERROR(VLOOKUP(I27,'BASE DE DADOS'!$A$4:$B$83,2,0)," ") | K27: =IFERROR(H27*J27," ") | L27: =IFERROR(IF(B27="TRAFO",K27,SUMIFS($L$11:$L$64,$A$11:$A$64,B27)+K27)," ")
... A64: 55 | D64: =ATUAL!K57 -> 0 | E64: =ATUAL!R57 -> 0 | F64: =D64+E64 -> 0 | G64: =SUMIF($B$11:$B$64,A64,$G$11:$G$64)+F64 -> 0 | H64: =(G64-(D64/2))*C64 -> 0 | J64: =IFERROR(VLOOKUP(I64,'BASE DE DADOS'!$A$4:$B$83,2,0)," ") | K64: =IFERROR(H64*J64," ") | L64: =IFERROR(IF(B64="TRAFO",K64,SUMIFS($L$11:$L$64,$A$11:$A$64,B64)+K64)," ")

Sheet ATUAL+NC
J1: TRECHO | K1: TOTAL | L1: MONO | M1: BI | N1: TRI | O1: TRI ESPECIAL | R1: TOTAL | S1: IP70W | T1: IP80W | U1: IP150W | V1: IP250W | W1: IP400W
A2: DEMANDA DIVERSIFICADA EM KVA | F2: LUMIN. | G2: QUANT | H2: DEMANDA | O2: QUANT | P2: CARGA
A3: TIPO DE LIGAÇÃO | C3: CLASSE "B" | F3: IP70W | G3: =SUM(S3:S57) -> 0 | H3: 0.07 | J3: TRAFO | K3: =SUM(L3:N3)*$C$5+P3 -> 75 | L3: =ATUAL!L3 -> 0 | M3: =ATUAL!M3 -> 0 | N3: =ATUAL!N3 -> 0 | O3: =ATUAL!O3 -> 1 | P3: =ATUAL!P3 -> 75 | R3: =S3*$H$3+T3*$H$4+U3*$H$5+V3*$H$6+W3*$H$7 -> 0 | U3: =ATUAL!U3 -> 0
A4: TOTAL DE CLIENTES | C4: =SUM(L3:O57) -> 4 | F4: IP80W | G4: =SUM(T3:T57) -> 0 | H4: 0.08 | J4: 2 | K4: =SUM(L4:N4)*$C$5+P4 -> 0 | L4: =ATUAL!L4 -> 0 | M4: =ATUAL!M4 -> 0 | N4: =ATUAL!N4 -> 0 | O4: =ATUAL!O4 -> 0 | P4: =ATUAL!P4 -> 0 | R4: =S4*$H$3+T4*$H$4+U4*$H$5+V4*$H$6+W4*$H$7 -> 0 | U4: =ATUAL!U4 -> 0
A5: DEMANDA UNITÁRIA | C5: =ATUAL!C5 -> 1.6 | F5: IP150W | G5: =SUM(U3:U57) -> 0 | H5: 0.15 | J5: 3 | K5: =SUM(L5:N5)*$C$5+P5 -> 0 | L5: =ATUAL!L5 -> 0 | M5: =ATUAL!M5 -> 0 | N5: =ATUAL!N5 -> 0 | O5: =ATUAL!O5 -> 0 | P5: =ATUAL!P5 -> 0 | R5: =S5*$H$3+T5*$H$4+U5*$H$5+V5*$H$6+W5*$H$7 -> 0 | U5: =ATUAL!U5 -> 0
F6: IP250W | G6: =SUM(V3:V57) -> 0 | H6: 0.25 | J6: 4 | K6: =SUM(L6:N6)*$C$5+P6 -> 0 | L6: =ATUAL!L6 -> 0 | M6: =ATUAL!M6 -> 0 | N6: =ATUAL!N6 -> 0 | O6: =ATUAL!O6 -> 0 | P6: =ATUAL!P6 -> 0 | R6: =S6*$H$3+T6*$H$4+U6*$H$5+V6*$H$6+W6*$H$7 -> 0 | U6: =ATUAL!U6 -> 0
F7: IP400W | G7: =SUM(W3:W57) -> 0 | H7: 0.4 | J7: 5 | K7: =SUM(L7:N7)*$C$5+P7 -> 49 | L7: =ATUAL!L7 -> 0 | M7: =ATUAL!M7 -> 0 | O7: 1 | P7: 49 | R7: =S7*$H$3+T7*$H$4+U7*$H$5+V7*$H$6+W7*$H$7 -> 0 | U7: =ATUAL!U7 -> 0
J8: 6 | K8: =SUM(L8:N8)*$C$5+P8 -> 3.2 | L8: =ATUAL!L8 -> 1 | M8: =ATUAL!M8 -> 0 | N8: =ATUAL!N8 -> 1 | O8: =ATUAL!O8 -> 0 | P8: =ATUAL!P8 -> 0 | R8: =S8*$H$3+T8*$H$4+U8*$H$5+V8*$H$6+W8*$H$7 -> 0 | U8: =ATUAL!U8 -> 0
J9: 7 | K9: =SUM(L9:N9)*$C$5+P9 -> 0 | L9: =ATUAL!L9 -> 0 | M9: =ATUAL!M9 -> 0 | N9: =ATUAL!N9 -> 0 | O9: =ATUAL!O9 -> 0 | P9: =ATUAL!P9 -> 0 | R9: =S9*$H$3+T9*$H$4+U9*$H$5+V9*$H$6+W9*$H$7 -> 0 | U9: =ATUAL!U9 -> 0
J10: 8 | K10: =SUM(L10:N10)*$C$5+P10 -> 0 | L10: =ATUAL!L10 -> 0 | M10: =ATUAL!M10 -> 0 | N10: =ATUAL!N10 -> 0 | O10: =ATUAL!O10 -> 0 | P10: =ATUAL!P10 -> 0 | R10: =S10*$H$3+T10*$H$4+U10*$H$5+V10*$H$6+W10*$H$7 -> 0 | U10: =ATUAL!U10 -> 0
J11: 9 | K11: =SUM(L11:N11)*$C$5+P11 -> 0 | L11: =ATUAL!L11 -> 0 | M11: =ATUAL!M11 -> 0 | N11: =ATUAL!N11 -> 0 | O11: =ATUAL!O11 -> 0 | P11: =ATUAL!P11 -> 0 | R11: =S11*$H$3+T11*$H$4+U11*$H$5+V11*$H$6+W11*$H$7 -> 0 | U11: =ATUAL!U11 -> 0
J12: 10 | K12: =SUM(L12:N12)*$C$5+P12 -> 0 | L12: =ATUAL!L12 -> 0 | M12: =ATUAL!M12 -> 0 | N12: =ATUAL!N12 -> 0 | O12: =ATUAL!O12 -> 0 | P12: =ATUAL!P12 -> 0 | R12: =S12*$H$3+T12*$H$4+U12*$H$5+V12*$H$6+W12*$H$7 -> 0 | U12: =ATUAL!U12 -> 0
J13: 11 | K13: =SUM(L13:N13)*$C$5+P13 -> 0 | L13: =ATUAL!L13 -> 0 | M13: =ATUAL!M13 -> 0 | N13: =ATUAL!N13 -> 0 | O13: =ATUAL!O13 -> 0 | P13: =ATUAL!P13 -> 0 | R13: =S13*$H$3+T13*$H$4+U13*$H$5+V13*$H$6+W13*$H$7 -> 0 | U13: =ATUAL!U13 -> 0
J14: 12 | K14: =SUM(L14:N14)*$C$5+P14 -> 0 | L14: =ATUAL!L14 -> 0 | M14: =ATUAL!M14 -> 0 | N14: =ATUAL!N14 -> 0 | O14: =ATUAL!O14 -> 0 | P14: =ATUAL!P14 -> 0 | R14: =S14*$H$3+T14*$H$4+U14*$H$5+V14*$H$6+W14*$H$7 -> 0 | U14: =ATUAL!U14 -> 0
J15: 13 | K15: =SUM(L15:N15)*$C$5+P15 -> 0 | L15: =ATUAL!L15 -> 0 | M15: =ATUAL!M15 -> 0 | N15: =ATUAL!N15 -> 0 | O15: =ATUAL!O15 -> 0 | P15: =ATUAL!P15 -> 0 | R15: =S15*$H$3+T15*$H$4+U15*$H$5+V15*$H$6+W15*$H$7 -> 0 | U15: =ATUAL!U15 -> 0
J16: 14 | K16: =SUM(L16:N16)*$C$5+P16 -> 0 | L16: =ATUAL!L16 -> 0 | M16: =ATUAL!M16 -> 0 | N16: =ATUAL!N16 -> 0 | O16: =ATUAL!O16 -> 0 | P16: =ATUAL!P16 -> 0 | R16: =S16*$H$3+T16*$H$4+U16*$H$5+V16*$H$6+W16*$H$7 -> 0 | U16: =ATUAL!U16 -> 0
J17: 15 | K17: =SUM(L17:N17)*$C$5+P17 -> 0 | L17: =ATUAL!L17 -> 0 | M17: =ATUAL!M17 -> 0 | N17: =ATUAL!N17 -> 0 | O17: =ATUAL!O17 -> 0 | P17: =ATUAL!P17 -> 0 | R17: =S17*$H$3+T17*$H$4+U17*$H$5+V17*$H$6+W17*$H$7 -> 0 | U17: =ATUAL!U17 -> 0
J18: 16 | K18: =SUM(L18:N18)*$C$5+P18 -> 0 | L18: =ATUAL!L18 -> 0 | M18: =ATUAL!M18 -> 0 | N18: =ATUAL!N18 -> 0 | O18: =ATUAL!O18 -> 0 | P18: =ATUAL!P18 -> 0 | R18: =S18*$H$3+T18*$H$4+U18*$H$5+V18*$H$6+W18*$H$7 -> 0 | U18: =ATUAL!U18 -> 0
J19: 17 | K19: =SUM(L19:N19)*$C$5+P19 -> 0 | L19: =ATUAL!L19 -> 0 | M19: =ATUAL!M19 -> 0 | N19: =ATUAL!N19 -> 0 | O19: =ATUAL!O19 -> 0 | P19: =ATUAL!P19 -> 0 | R19: =S19*$H$3+T19*$H$4+U19*$H$5+V19*$H$6+W19*$H$7 -> 0 | U19: =ATUAL!U19 -> 0
... J57: 55 | K57: =SUM(L57:N57)*$C$5+P57 -> 0 | L57: =ATUAL!L57 -> 0 | M57: =ATUAL!M57 -> 0 | N57: =ATUAL!N57 -> 0 | O57: =ATUAL!O57 -> 0 | P57: =ATUAL!P57 -> 0 | R57: =S57*$H$3+T57*$H$4+U57*$H$5+V57*$H$6+W57*$H$7 -> 0 | U57: =ATUAL!U57 -> 0

Sheet CQT ATUAL+NC
A1: PROJETO | B1: ='CQT ATUAL'!B1 -> A052750522 | G1: CARREGAMENTO TRANSFORMADOR
A3: SUBESTAÇÃO | B3: SANTA CLARA | D3: POTÊNCIA DO TRANSFORMADOR - kVA | F3: ='CQT ATUAL'!F3 -> 75 | G3: =(F5)/F3 -> 1.696
A4: TAXA DE CRESCIMENTO ANUAL | B4: =VLOOKUP(B3,'BASE DE DADOS'!P:R,2,0) -> 0.035 | D4: PONTO ELÉTRICO DO TRANSFORMADOR | F4: ='CQT ATUAL'!F4 -> C380653
A5: FATOR MULTIPLICATIVO 5 ANOS | B5: 1 | D5: DEMANDA TOTAL DO CIRCUITO DE BT - kVA | F5: =SUM('ATUAL+NC'!K3:K57)+SUM('ATUAL+NC'!R3:R57) -> 127.2
A7: TRECHOS | D7: CARGAS | I7: CONDUTOR | J7: QUEDA DE TENSÃO
A8: TRECHO | B8: TRECHO MONTANTE | C8: COMPRIMENTO | D8: DISTRIBUÍDA NO TRECHO | G8: ACUMULADA NO FINAL DO TRECHO | H8: TOTAL (C/2+D)*B | J8: UNITÁRIO | K8: NO TRECHO | L8: TOTAL
A9: A | C9: B - 100 | D9: C - kVA | G9: D - kVA | H9: E - kVA x B | I9: F - mm² | J9: G - % | K9: H - % | L9: I - %
D10: CLIENTES | E10: ILUMINAÇÃO PÚBLICA | F10: TOTAL DO TRECHO
A11: 2 | B11: ='CQT ATUAL'!B11 -> TRAFO | C11: ='CQT ATUAL'!C11 -> 0.35 | D11: ='ATUAL+NC'!K4 -> 0 | E11: ='ATUAL+NC'!R4 -> 0 | F11: =D11+E11 -> 0 | G11: =SUMIF($B$11:$B$64,A11,$G$11:$G$64)+F11 -> 52.2 | H11: =((D11/2)+G11)*C11 -> 18.27 | I11: 3x50+1x50 - Al - F.P 1 | J11: =IFERROR(VLOOKUP(I11,'BASE DE DADOS'!$A$4:$B$83,2,0)," ") -> 0.1784 | K11: =IFERROR(H11*J11," ") -> 3.259368 | L11: =IFERROR(IF(B11="TRAFO",K11,SUMIFS($L$11:$L$64,$A$11:$A$64,B11)+K11)," ") -> 3.259368
A12: 3 | B12: ='CQT ATUAL'!B12 -> 2 | C12: ='CQT ATUAL'!C12 -> 0.12 | D12: ='ATUAL+NC'!K5 -> 0 | E12: ='ATUAL+NC'!R5 -> 0 | F12: =D12+E12 -> 0 | G12: =SUMIF($B$11:$B$64,A12,$G$11:$G$64)+F12 -> 52.2 | H12: =((D12/2)+G12)*C12 -> 6.264 | I12: 3x50+1x50 - Al - F.P 1 | J12: =IFERROR(VLOOKUP(I12,'BASE DE DADOS'!$A$4:$B$83,2,0)," ") -> 0.1784 | K12: =IFERROR(H12*J12," ") -> 1.1174976 | L12: =IFERROR(IF(B12="TRAFO",K12,SUMIFS($L$11:$L$64,$A$11:$A$64,B12)+K12)," ") -> 4.3768656
A13: 4 | B13: ='CQT ATUAL'!B13 -> 3 | C13: ='CQT ATUAL'!C13 -> 0.4 | D13: ='ATUAL+NC'!K6 -> 0 | E13: ='ATUAL+NC'!R6 -> 0 | F13: =D13+E13 -> 0 | G13: =SUMIF($B$11:$B$64,A13,$G$11:$G$64)+F13 -> 52.2 | H13: =((D13/2)+G13)*C13 -> 20.88 | I13: 3x50+1x50 - Al - F.P 1 | J13: =IFERROR(VLOOKUP(I13,'BASE DE DADOS'!$A$4:$B$83,2,0)," ") -> 0.1784 | K13: =IFERROR(H13*J13," ") -> 3.724992 | L13: =IFERROR(IF(B13="TRAFO",K13,SUMIFS($L$11:$L$64,$A$11:$A$64,B13)+K13)," ") -> 8.1018576
A14: 5 | B14: ='CQT ATUAL'!B14 -> 4 | C14: ='CQT ATUAL'!C14 -> 0.4 | D14: ='ATUAL+NC'!K7 -> 49 | E14: ='ATUAL+NC'!R7 -> 0 | F14: =D14+E14 -> 49 | G14: =SUMIF($B$11:$B$64,A14,$G$11:$G$64)+F14 -> 52.2 | H14: =((D14/2)+G14)*C14 -> 30.68 | I14: 3x50+1x50 - Al - F.P 1 | J14: =IFERROR(VLOOKUP(I14,'BASE DE DADOS'!$A$4:$B$83,2,0)," ") -> 0.1784 | K14: =IFERROR(H14*J14," ") -> 5.473312 | L14: =IFERROR(IF(B14="TRAFO",K14,SUMIFS($L$11:$L$64,$A$11:$A$64,B14)+K14)," ") -> 13.57517
A15: 6 | B15: ='CQT ATUAL'!B15 -> 5 | C15: ='CQT ATUAL'!C15 -> 0.4 | D15: ='ATUAL+NC'!K8 -> 3.2 | E15: ='ATUAL+NC'!R8 -> 0 | F15: =D15+E15 -> 3.2 | G15: =SUMIF($B$11:$B$64,A15,$G$11:$G$64)+F15 -> 3.2 | H15: =((D15/2)+G15)*C15 -> 1.92 | I15: 3x50+1x50 - Al - F.P 1 | J15: =IFERROR(VLOOKUP(I15,'BASE DE DADOS'!$A$4:$B$83,2,0)," ") -> 0.1784 | K15: =IFERROR(H15*J15," ") -> 0.342528 | L15: =IFERROR(IF(B15="TRAFO",K15,SUMIFS($L$11:$L$64,$A$11:$A$64,B15)+K15)," ") -> 13.917698
A16: 7 | B16: ='CQT ATUAL'!B16 -> 0 | C16: ='CQT ATUAL'!C16 -> 0 | D16: ='ATUAL+NC'!K9 -> 0 | E16: ='ATUAL+NC'!R9 -> 0 | F16: =D16+E16 -> 0 | G16: =SUMIF($B$11:$B$64,A16,$G$11:$G$64)+F16 -> 0 | H16: =((D16/2)+G16)*C16 -> 0 | J16: =IFERROR(VLOOKUP(I16,'BASE DE DADOS'!$A$4:$B$83,2,0)," ") | K16: =IFERROR(H16*J16," ") | L16: =IFERROR(IF(B16="TRAFO",K16,SUMIFS($L$11:$L$64,$A$11:$A$64,B16)+K16)," ")
A17: 8 | B17: ='CQT ATUAL'!B17 -> 0 | C17: ='CQT ATUAL'!C17 -> 0 | D17: ='ATUAL+NC'!K10 -> 0 | E17: ='ATUAL+NC'!R10 -> 0 | F17: =D17+E17 -> 0 | G17: =SUMIF($B$11:$B$64,A17,$G$11:$G$64)+F17 -> 0 | H17: =((D17/2)+G17)*C17 -> 0 | J17: =IFERROR(VLOOKUP(I17,'BASE DE DADOS'!$A$4:$B$83,2,0)," ") | K17: =IFERROR(H17*J17," ") | L17: =IFERROR(IF(B17="TRAFO",K17,SUMIFS($L$11:$L$64,$A$11:$A$64,B17)+K17)," ")
A18: 9 | B18: ='CQT ATUAL'!B18 -> 0 | C18: ='CQT ATUAL'!C18 -> 0 | D18: ='ATUAL+NC'!K11 -> 0 | E18: ='ATUAL+NC'!R11 -> 0 | F18: =D18+E18 -> 0 | G18: =SUMIF($B$11:$B$64,A18,$G$11:$G$64)+F18 -> 0 | H18: =((D18/2)+G18)*C18 -> 0 | J18: =IFERROR(VLOOKUP(I18,'BASE DE DADOS'!$A$4:$B$83,2,0)," ") | K18: =IFERROR(H18*J18," ") | L18: =IFERROR(IF(B18="TRAFO",K18,SUMIFS($L$11:$L$64,$A$11:$A$64,B18)+K18)," ")
A19: 10 | B19: ='CQT ATUAL'!B19 -> 0 | C19: ='CQT ATUAL'!C19 -> 0 | D19: ='ATUAL+NC'!K12 -> 0 | E19: ='ATUAL+NC'!R12 -> 0 | F19: =D19+E19 -> 0 | G19: =SUMIF($B$11:$B$64,A19,$G$11:$G$64)+F19 -> 0 | H19: =((D19/2)+G19)*C19 -> 0 | J19: =IFERROR(VLOOKUP(I19,'BASE DE DADOS'!$A$4:$B$83,2,0)," ") | K19: =IFERROR(H19*J19," ") | L19: =IFERROR(IF(B19="TRAFO",K19,SUMIFS($L$11:$L$64,$A$11:$A$64,B19)+K19)," ")
A20: 11 | B20: ='CQT ATUAL'!B20 -> 0 | C20: ='CQT ATUAL'!C20 -> 0 | D20: ='ATUAL+NC'!K13 -> 0 | E20: ='ATUAL+NC'!R13 -> 0 | F20: =D20+E20 -> 0 | G20: =SUMIF($B$11:$B$64,A20,$G$11:$G$64)+F20 -> 0 | H20: =((D20/2)+G20)*C20 -> 0 | J20: =IFERROR(VLOOKUP(I20,'BASE DE DADOS'!$A$4:$B$83,2,0)," ") | K20: =IFERROR(H20*J20," ") | L20: =IFERROR(IF(B20="TRAFO",K20,SUMIFS($L$11:$L$64,$A$11:$A$64,B20)+K20)," ")
A21: 12 | B21: ='CQT ATUAL'!B21 -> 0 | C21: ='CQT ATUAL'!C21 -> 0 | D21: ='ATUAL+NC'!K14 -> 0 | E21: ='ATUAL+NC'!R14 -> 0 | F21: =D21+E21 -> 0 | G21: =SUMIF($B$11:$B$64,A21,$G$11:$G$64)+F21 -> 0 | H21: =((D21/2)+G21)*C21 -> 0 | J21: =IFERROR(VLOOKUP(I21,'BASE DE DADOS'!$A$4:$B$83,2,0)," ") | K21: =IFERROR(H21*J21," ") | L21: =IFERROR(IF(B21="TRAFO",K21,SUMIFS($L$11:$L$64,$A$11:$A$64,B21)+K21)," ")
A22: 13 | B22: ='CQT ATUAL'!B22 -> 0 | C22: ='CQT ATUAL'!C22 -> 0 | D22: ='ATUAL+NC'!K15 -> 0 | E22: ='ATUAL+NC'!R15 -> 0 | F22: =D22+E22 -> 0 | G22: =SUMIF($B$11:$B$64,A22,$G$11:$G$64)+F22 -> 0 | H22: =((D22/2)+G22)*C22 -> 0 | J22: =IFERROR(VLOOKUP(I22,'BASE DE DADOS'!$A$4:$B$83,2,0)," ") | K22: =IFERROR(H22*J22," ") | L22: =IFERROR(IF(B22="TRAFO",K22,SUMIFS($L$11:$L$64,$A$11:$A$64,B22)+K22)," ")
A23: 14 | B23: ='CQT ATUAL'!B23 -> 0 | C23: ='CQT ATUAL'!C23 -> 0 | D23: ='ATUAL+NC'!K16 -> 0 | E23: ='ATUAL+NC'!R16 -> 0 | F23: =D23+E23 -> 0 | G23: =SUMIF($B$11:$B$64,A23,$G$11:$G$64)+F23 -> 0 | H23: =((D23/2)+G23)*C23 -> 0 | J23: =IFERROR(VLOOKUP(I23,'BASE DE DADOS'!$A$4:$B$83,2,0)," ") | K23: =IFERROR(H23*J23," ") | L23: =IFERROR(IF(B23="TRAFO",K23,SUMIFS($L$11:$L$64,$A$11:$A$64,B23)+K23)," ")
A24: 15 | B24: ='CQT ATUAL'!B24 -> 0 | C24: ='CQT ATUAL'!C24 -> 0 | D24: ='ATUAL+NC'!K17 -> 0 | E24: ='ATUAL+NC'!R17 -> 0 | F24: =D24+E24 -> 0 | G24: =SUMIF($B$11:$B$64,A24,$G$11:$G$64)+F24 -> 0 | H24: =((D24/2)+G24)*C24 -> 0 | J24: =IFERROR(VLOOKUP(I24,'BASE DE DADOS'!$A$4:$B$83,2,0)," ") | K24: =IFERROR(H24*J24," ") | L24: =IFERROR(IF(B24="TRAFO",K24,SUMIFS($L$11:$L$64,$A$11:$A$64,B24)+K24)," ")
A25: 16 | B25: ='CQT ATUAL'!B25 -> 0 | C25: ='CQT ATUAL'!C25 -> 0 | D25: ='ATUAL+NC'!K18 -> 0 | E25: ='ATUAL+NC'!R18 -> 0 | F25: =D25+E25 -> 0 | G25: =SUMIF($B$11:$B$64,A25,$G$11:$G$64)+F25 -> 0 | H25: =((D25/2)+G25)*C25 -> 0 | J25: =IFERROR(VLOOKUP(I25,'BASE DE DADOS'!$A$4:$B$83,2,0)," ") | K25: =IFERROR(H25*J25," ") | L25: =IFERROR(IF(B25="TRAFO",K25,SUMIFS($L$11:$L$64,$A$11:$A$64,B25)+K25)," ")
A26: 17 | B26: ='CQT ATUAL'!B26 -> 0 | C26: ='CQT ATUAL'!C26 -> 0 | D26: ='ATUAL+NC'!K19 -> 0 | E26: ='ATUAL+NC'!R19 -> 0 | F26: =D26+E26 -> 0 | G26: =SUMIF($B$11:$B$64,A26,$G$11:$G$64)+F26 -> 0 | H26: =((D26/2)+G26)*C26 -> 0 | J26: =IFERROR(VLOOKUP(I26,'BASE DE DADOS'!$A$4:$B$83,2,0)," ") | K26: =IFERROR(H26*J26," ") | L26: =IFERROR(IF(B26="TRAFO",K26,SUMIFS($L$11:$L$64,$A$11:$A$64,B26)+K26)," ")
A27: 18 | B27: ='CQT ATUAL'!B27 -> 0 | C27: ='CQT ATUAL'!C27 -> 0 | D27: ='ATUAL+NC'!K20 -> 0 | E27: ='ATUAL+NC'!R20 -> 0 | F27: =D27+E27 -> 0 | G27: =SUMIF($B$11:$B$64,A27,$G$11:$G$64)+F27 -> 0 | H27: =((D27/2)+G27)*C27 -> 0 | J27: =IFERROR(VLOOKUP(I27,'BASE DE DADOS'!$A$4:$B$83,2,0)," ") | K27: =IFERROR(H27*J27," ") | L27: =IFERROR(IF(B27="TRAFO",K27,SUMIFS($L$11:$L$64,$A$11:$A$64,B27)+K27)," ")
... A64: 55 | B64: ='CQT ATUAL'!B64 -> 0 | C64: ='CQT ATUAL'!C64 -> 0 | D64: ='ATUAL+NC'!K57 -> 0 | E64: ='ATUAL+NC'!R57 -> 0 | F64: =D64+E64 -> 0 | G64: =SUMIF($B$11:$B$64,A64,$G$11:$G$64)+F64 -> 0 | H64: =((D64/2)+G64)*C64 -> 0 | J64: =IFERROR(VLOOKUP(I64,'BASE DE DADOS'!$A$4:$B$83,2,0)," ") | K64: =IFERROR(H64*J64," ") | L64: =IFERROR(IF(B64="TRAFO",K64,SUMIFS($L$11:$L$64,$A$11:$A$64,B64)+K64)," ")

Sheet PROJ 01
J1: TRECHO | K1: TOTAL | L1: MONO | M1: BI | N1: TRI | O1: TRI ESPECIAL | R1: TOTAL | S1: IP70W | T1: IP80W | U1: IP150W | V1: IP250W | W1: IP400W
A2: DEMANDA DIVERSIFICADA EM KVA | F2: LUMIN. | G2: QUANT | H2: DEMANDA | O2: QUANT | P2: CARGA
A3: TIPO DE LIGAÇÃO | C3: CLASSE "B" | F3: IP70W | G3: =SUM(S3:S57) -> 0 | H3: 0.07 | J3: TRAFO | K3: =SUM(L3:N3)*$C$5+P3 -> 0 | L3: =ATUAL!L3 -> 0 | M3: =ATUAL!M3 -> 0 | N3: =ATUAL!N3 -> 0 | R3: =S3*$H$3+T3*$H$4+U3*$H$5+V3*$H$6+W3*$H$7 -> 0
A4: TOTAL DE CLIENTES | C4: =SUM(L3:O57) -> 3 | F4: IP80W | G4: =SUM(T3:T57) -> 0 | H4: 0.08 | J4: 2 | K4: =SUM(L4:N4)*$C$5+P4 -> 0 | L4: =ATUAL!L4 -> 0 | M4: =ATUAL!M4 -> 0 | N4: =ATUAL!N4 -> 0 | O4: =ATUAL!O4 -> 0 | P4: =ATUAL!P4 -> 0 | R4: =S4*$H$3+T4*$H$4+U4*$H$5+V4*$H$6+W4*$H$7 -> 0
A5: DEMANDA UNITÁRIA | C5: =ATUAL!C5 -> 1.6 | F5: IP150W | G5: =SUM(U3:U57) -> 0 | H5: 0.15 | J5: 3 | K5: =SUM(L5:N5)*$C$5+P5 -> 0 | L5: =ATUAL!L5 -> 0 | M5: =ATUAL!M5 -> 0 | N5: =ATUAL!N5 -> 0 | O5: =ATUAL!O5 -> 0 | P5: =ATUAL!P5 -> 0 | R5: =S5*$H$3+T5*$H$4+U5*$H$5+V5*$H$6+W5*$H$7 -> 0
F6: IP250W | G6: =SUM(V3:V57) -> 0 | H6: 0.25 | J6: 4 | K6: =SUM(L6:N6)*$C$5+P6 -> 0 | L6: =ATUAL!L6 -> 0 | M6: =ATUAL!M6 -> 0 | N6: =ATUAL!N6 -> 0 | O6: =ATUAL!O6 -> 0 | P6: =ATUAL!P6 -> 0 | R6: =S6*$H$3+T6*$H$4+U6*$H$5+V6*$H$6+W6*$H$7 -> 0
F7: IP400W | G7: =SUM(W3:W57) -> 0 | H7: 0.4 | J7: 5 | K7: =SUM(L7:N7)*$C$5+P7 -> 49 | L7: =ATUAL!L7 -> 0 | M7: =ATUAL!M7 -> 0 | O7: 1 | P7: 49 | R7: =S7*$H$3+T7*$H$4+U7*$H$5+V7*$H$6+W7*$H$7 -> 0
J8: 6 | K8: =SUM(L8:N8)*$C$5+P8 -> 3.2 | L8: =ATUAL!L8 -> 1 | M8: =ATUAL!M8 -> 0 | N8: =ATUAL!N8 -> 1 | O8: =ATUAL!O8 -> 0 | P8: =ATUAL!P8 -> 0 | R8: =S8*$H$3+T8*$H$4+U8*$H$5+V8*$H$6+W8*$H$7 -> 0
J9: 7 | K9: =SUM(L9:N9)*$C$5+P9 -> 0 | L9: =ATUAL!L9 -> 0 | M9: =ATUAL!M9 -> 0 | N9: =ATUAL!N9 -> 0 | O9: =ATUAL!O9 -> 0 | P9: =ATUAL!P9 -> 0 | R9: =S9*$H$3+T9*$H$4+U9*$H$5+V9*$H$6+W9*$H$7 -> 0
J10: 8 | K10: =SUM(L10:N10)*$C$5+P10 -> 0 | R10: =S10*$H$3+T10*$H$4+U10*$H$5+V10*$H$6+W10*$H$7 -> 0
J11: 9 | K11: =SUM(L11:N11)*$C$5+P11 -> 0 | R11: =S11*$H$3+T11*$H$4+U11*$H$5+V11*$H$6+W11*$H$7 -> 0
J12: 10 | K12: =SUM(L12:N12)*$C$5+P12 -> 0 | R12: =S12*$H$3+T12*$H$4+U12*$H$5+V12*$H$6+W12*$H$7 -> 0
J13: 11 | K13: =SUM(L13:N13)*$C$5+P13 -> 0 | R13: =S13*$H$3+T13*$H$4+U13*$H$5+V13*$H$6+W13*$H$7 -> 0
J14: 12 | K14: =SUM(L14:N14)*$C$5+P14 -> 0 | R14: =S14*$H$3+T14*$H$4+U14*$H$5+V14*$H$6+W14*$H$7 -> 0
J15: 13 | K15: =SUM(L15:N15)*$C$5+P15 -> 0 | R15: =S15*$H$3+T15*$H$4+U15*$H$5+V15*$H$6+W15*$H$7 -> 0
J16: 14 | K16: =SUM(L16:N16)*$C$5+P16 -> 0 | R16: =S16*$H$3+T16*$H$4+U16*$H$5+V16*$H$6+W16*$H$7 -> 0
J17: 15 | K17: =SUM(L17:N17)*$C$5+P17 -> 0 | R17: =S17*$H$3+T17*$H$4+U17*$H$5+V17*$H$6+W17*$H$7 -> 0
J18: 16 | K18: =SUM(L18:N18)*$C$5+P18 -> 0 | R18: =S18*$H$3+T18*$H$4+U18*$H$5+V18*$H$6+W18*$H$7 -> 0
J19: 17 | K19: =SUM(L19:N19)*$C$5+P19 -> 0 | R19: =S19*$H$3+T19*$H$4+U19*$H$5+V19*$H$6+W19*$H$7 -> 0
J20: 18 | K20: =SUM(L20:N20)*$C$5+P20 -> 0 | R20: =S20*$H$3+T20*$H$4+U20*$H$5+V20*$H$6+W20*$H$7 -> 0
J21: 19 | K21: =SUM(L21:N21)*$C$5+P21 -> 0 | R21: =S21*$H$3+T21*$H$4+U21*$H$5+V21*$H$6+W21*$H$7 -> 0
... J57: 55 | K57: =SUM(L57:N57)*$C$5+P57 -> 0 | R57: =S57*$H$3+T57*$H$4+U57*$H$5+V57*$H$6+W57*$H$7 -> 0

Sheet CQT PROJ 01
A1: PROJETO | B1: ='CQT ATUAL'!B1 -> A052750522 | G1: CARREGAMENTO TRANSFORMADOR
A3: SUBESTAÇÃO | B3: SANTA CLARA | D3: POTÊNCIA DO TRANSFORMADOR - kVA | F3: 75 | G3: =(F5)/F3 -> 0.696
A4: TAXA DE CRESCIMENTO ANUAL | B4: =VLOOKUP(B3,'BASE DE DADOS'!P:R,2,0) -> 0.035 | D4: PONTO ELÉTRICO DO TRANSFORMADOR | F4: ='CQT ATUAL+NC'!F4 -> C380653
A5: FATOR MULTIPLICATIVO 5 ANOS | B5: =VLOOKUP(B3,'BASE DE DADOS'!P:R,3,0) -> 1.217 | D5: DEMANDA TOTAL DO CIRCUITO DE BT - kVA | F5: =SUM('PROJ 01'!K3:K42)+SUM('PROJ 01'!R3:R42) -> 52.2
A7: TRECHOS | D7: CARGAS | I7: CONDUTOR | J7: QUEDA DE TENSÃO
A8: TRECHO | B8: TRECHO MONTANTE | C8: COMPRIMENTO | D8: DISTRIBUÍDA NO TRECHO | G8: ACUMULADA NO FINAL DO TRECHO | H8: TOTAL (C/2+D)*B | J8: UNITÁRIO | K8: NO TRECHO | L8: TOTAL
A9: A | C9: B - 100 | D9: C - kVA | G9: D - kVA | H9: E - kVA x B | I9: F - mm² | J9: G - % | K9: H - % | L9: I - %
D10: CLIENTES | E10: ILUMINAÇÃO PÚBLICA | F10: TOTAL DO TRECHO
A11: 2 | B11: ='CQT ATUAL'!B11 -> TRAFO | C11: 0.17 | D11: ='PROJ 01'!K4 -> 0 | E11: ='PROJ 01'!R4 -> 0 | F11: =D11+E11 -> 0 | G11: =SUMIF($B$11:$B$64,A11,$G$11:$G$64)+F11 -> 52.2 | H11: =((D11/2)+G11)*C11 -> 8.874 | I11: 3x150+1x80 - Al - F.P 1 | J11: =IFERROR(VLOOKUP(I11,'BASE DE DADOS'!$A$4:$B$83,2,0)," ") -> 0.0573 | K11: =IFERROR(H11*J11," ") -> 0.5084802 | L11: =IFERROR(IF(B11="TRAFO",K11,SUMIFS($L$11:$L$64,$A$11:$A$64,B11)+K11)," ") -> 0.5084802
A12: 3 | B12: 2 | C12: ='CQT ATUAL'!C12 -> 0.12 | D12: ='PROJ 01'!K5 -> 0 | E12: ='PROJ 01'!R5 -> 0 | F12: =D12+E12 -> 0 | G12: =SUMIF($B$11:$B$64,A12,$G$11:$G$64)+F12 -> 52.2 | H12: =((D12/2)+G12)*C12 -> 6.264 | I12: 3x95+1x54,6 - Al - F.P 1 | J12: =IFERROR(VLOOKUP(I12,'BASE DE DADOS'!$A$4:$B$83,2,0)," ") -> 0.0891 | K12: =IFERROR(H12*J12," ") -> 0.5581224 | L12: =IFERROR(IF(B12="TRAFO",K12,SUMIFS($L$11:$L$64,$A$11:$A$64,B12)+K12)," ") -> 1.0666026
A13: 4 | B13: ='CQT ATUAL'!B13 -> 3 | C13: ='CQT ATUAL'!C13 -> 0.4 | D13: ='PROJ 01'!K6 -> 0 | E13: ='PROJ 01'!R6 -> 0 | F13: =D13+E13 -> 0 | G13: =SUMIF($B$11:$B$64,A13,$G$11:$G$64)+F13 -> 52.2 | H13: =((D13/2)+G13)*C13 -> 20.88 | I13: 3x95+1x54,6 - Al - F.P 1 | J13: =IFERROR(VLOOKUP(I13,'BASE DE DADOS'!$A$4:$B$83,2,0)," ") -> 0.0891 | K13: =IFERROR(H13*J13," ") -> 1.860408 | L13: =IFERROR(IF(B13="TRAFO",K13,SUMIFS($L$11:$L$64,$A$11:$A$64,B13)+K13)," ") -> 2.9270106
A14: 5 | B14: ='CQT ATUAL'!B14 -> 4 | C14: ='CQT ATUAL'!C14 -> 0.4 | D14: ='PROJ 01'!K7 -> 49 | E14: ='PROJ 01'!R7 -> 0 | F14: =D14+E14 -> 49 | G14: =SUMIF($B$11:$B$64,A14,$G$11:$G$64)+F14 -> 52.2 | H14: =((D14/2)+G14)*C14 -> 30.68 | I14: 3x95+1x54,6 - Al - F.P 1 | J14: =IFERROR(VLOOKUP(I14,'BASE DE DADOS'!$A$4:$B$83,2,0)," ") -> 0.0891 | K14: =IFERROR(H14*J14," ") -> 2.733588 | L14: =IFERROR(IF(B14="TRAFO",K14,SUMIFS($L$11:$L$64,$A$11:$A$64,B14)+K14)," ") -> 5.6605986
A15: 6 | B15: ='CQT ATUAL'!B15 -> 5 | C15: ='CQT ATUAL'!C15 -> 0.4 | D15: ='PROJ 01'!K8 -> 3.2 | E15: ='PROJ 01'!R8 -> 0 | F15: =D15+E15 -> 3.2 | G15: =SUMIF($B$11:$B$64,A15,$G$11:$G$64)+F15 -> 3.2 | H15: =((D15/2)+G15)*C15 -> 1.92 | I15: 3x50+1x50 - Al - F.P 1 | J15: =IFERROR(VLOOKUP(I15,'BASE DE DADOS'!$A$4:$B$83,2,0)," ") -> 0.1784 | K15: =IFERROR(H15*J15," ") -> 0.342528 | L15: =IFERROR(IF(B15="TRAFO",K15,SUMIFS($L$11:$L$64,$A$11:$A$64,B15)+K15)," ") -> 6.0031266
A16: 7 | D16: ='PROJ 01'!K9 -> 0 | E16: ='PROJ 01'!R9 -> 0 | F16: =D16+E16 -> 0 | G16: =SUMIF($B$11:$B$64,A16,$G$11:$G$64)+F16 -> 0 | H16: =((D16/2)+G16)*C16 -> 0 | J16: =IFERROR(VLOOKUP(I16,'BASE DE DADOS'!$A$4:$B$83,2,0)," ") | K16: =IFERROR(H16*J16," ") | L16: =IFERROR(IF(B16="TRAFO",K16,SUMIFS($L$11:$L$64,$A$11:$A$64,B16)+K16)," ")
A17: 8 | D17: ='PROJ 01'!K10 -> 0 | E17: ='PROJ 01'!R10 -> 0 | F17: =D17+E17 -> 0 | G17: =SUMIF($B$11:$B$64,A17,$G$11:$G$64)+F17 -> 0 | H17: =((D17/2)+G17)*C17 -> 0 | J17: =IFERROR(VLOOKUP(I17,'BASE DE DADOS'!$A$4:$B$83,2,0)," ") | K17: =IFERROR(H17*J17," ") | L17: =IFERROR(IF(B17="TRAFO",K17,SUMIFS($L$11:$L$64,$A$11:$A$64,B17)+K17)," ")
A18: 9 | D18: ='PROJ 01'!K11 -> 0 | E18: ='PROJ 01'!R11 -> 0 | F18: =D18+E18 -> 0 | G18: =SUMIF($B$11:$B$64,A18,$G$11:$G$64)+F18 -> 0 | H18: =((D18/2)+G18)*C18 -> 0 | J18: =IFERROR(VLOOKUP(I18,'BASE DE DADOS'!$A$4:$B$83,2,0)," ") | K18: =IFERROR(H18*J18," ") | L18: =IFERROR(IF(B18="TRAFO",K18,SUMIFS($L$11:$L$64,$A$11:$A$64,B18)+K18)," ")
A19: 10 | D19: ='PROJ 01'!K12 -> 0 | E19: ='PROJ 01'!R12 -> 0 | F19: =D19+E19 -> 0 | G19: =SUMIF($B$11:$B$64,A19,$G$11:$G$64)+F19 -> 0 | H19: =((D19/2)+G19)*C19 -> 0 | J19: =IFERROR(VLOOKUP(I19,'BASE DE DADOS'!$A$4:$B$83,2,0)," ") | K19: =IFERROR(H19*J19," ") | L19: =IFERROR(IF(B19="TRAFO",K19,SUMIFS($L$11:$L$64,$A$11:$A$64,B19)+K19)," ")
A20: 11 | D20: ='PROJ 01'!K13 -> 0 | E20: ='PROJ 01'!R13 -> 0 | F20: =D20+E20 -> 0 | G20: =SUMIF($B$11:$B$64,A20,$G$11:$G$64)+F20 -> 0 | H20: =((D20/2)+G20)*C20 -> 0 | J20: =IFERROR(VLOOKUP(I20,'BASE DE DADOS'!$A$4:$B$83,2,0)," ") | K20: =IFERROR(H20*J20," ") | L20: =IFERROR(IF(B20="TRAFO",K20,SUMIFS($L$11:$L$64,$A$11:$A$64,B20)+K20)," ")
A21: 12 | D21: ='PROJ 01'!K14 -> 0 | E21: ='PROJ 01'!R14 -> 0 | F21: =D21+E21 -> 0 | G21: =SUMIF($B$11:$B$64,A21,$G$11:$G$64)+F21 -> 0 | H21: =((D21/2)+G21)*C21 -> 0 | J21: =IFERROR(VLOOKUP(I21,'BASE DE DADOS'!$A$4:$B$83,2,0)," ") | K21: =IFERROR(H21*J21," ") | L21: =IFERROR(IF(B21="TRAFO",K21,SUMIFS($L$11:$L$64,$A$11:$A$64,B21)+K21)," ")
A22: 13 | D22: ='PROJ 01'!K15 -> 0 | E22: ='PROJ 01'!R15 -> 0 | F22: =D22+E22 -> 0 | G22: =SUMIF($B$11:$B$64,A22,$G$11:$G$64)+F22 -> 0 | H22: =((D22/2)+G22)*C22 -> 0 | J22: =IFERROR(VLOOKUP(I22,'BASE DE DADOS'!$A$4:$B$83,2,0)," ") | K22: =IFERROR(H22*J22," ") | L22: =IFERROR(IF(B22="TRAFO",K22,SUMIFS($L$11:$L$64,$A$11:$A$64,B22)+K22)," ")
A23: 14 | D23: ='PROJ 01'!K16 -> 0 | E23: ='PROJ 01'!R16 -> 0 | F23: =D23+E23 -> 0 | G23: =SUMIF($B$11:$B$64,A23,$G$11:$G$64)+F23 -> 0 | H23: =((D23/2)+G23)*C23 -> 0 | J23: =IFERROR(VLOOKUP(I23,'BASE DE DADOS'!$A$4:$B$83,2,0)," ") | K23: =IFERROR(H23*J23," ") | L23: =IFERROR(IF(B23="TRAFO",K23,SUMIFS($L$11:$L$64,$A$11:$A$64,B23)+K23)," ")
A24: 15 | D24: ='PROJ 01'!K17 -> 0 | E24: ='PROJ 01'!R17 -> 0 | F24: =D24+E24 -> 0 | G24: =SUMIF($B$11:$B$64,A24,$G$11:$G$64)+F24 -> 0 | H24: =((D24/2)+G24)*C24 -> 0 | J24: =IFERROR(VLOOKUP(I24,'BASE DE DADOS'!$A$4:$B$83,2,0)," ") | K24: =IFERROR(H24*J24," ") | L24: =IFERROR(IF(B24="TRAFO",K24,SUMIFS($L$11:$L$64,$A$11:$A$64,B24)+K24)," ")
A25: 16 | D25: ='PROJ 01'!K18 -> 0 | E25: ='PROJ 01'!R18 -> 0 | F25: =D25+E25 -> 0 | G25: =SUMIF($B$11:$B$64,A25,$G$11:$G$64)+F25 -> 0 | H25: =((D25/2)+G25)*C25 -> 0 | J25: =IFERROR(VLOOKUP(I25,'BASE DE DADOS'!$A$4:$B$83,2,0)," ") | K25: =IFERROR(H25*J25," ") | L25: =IFERROR(IF(B25="TRAFO",K25,SUMIFS($L$11:$L$64,$A$11:$A$64,B25)+K25)," ")
A26: 17 | D26: ='PROJ 01'!K19 -> 0 | E26: ='PROJ 01'!R19 -> 0 | F26: =D26+E26 -> 0 | G26: =SUMIF($B$11:$B$64,A26,$G$11:$G$64)+F26 -> 0 | H26: =((D26/2)+G26)*C26 -> 0 | J26: =IFERROR(VLOOKUP(I26,'BASE DE DADOS'!$A$4:$B$83,2,0)," ") | K26: =IFERROR(H26*J26," ") | L26: =IFERROR(IF(B26="TRAFO",K26,SUMIFS($L$11:$L$64,$A$11:$A$64,B26)+K26)," ")
A27: 18 | D27: ='PROJ 01'!K20 -> 0 | E27: ='PROJ 01'!R20 -> 0 | F27: =D27+E27 -> 0 | G27: =SUMIF($B$11:$B$64,A27,$G$11:$G$64)+F27 -> 0 | H27: =((D27/2)+G27)*C27 -> 0 | J27: =IFERROR(VLOOKUP(I27,'BASE DE DADOS'!$A$4:$B$83,2,0)," ") | K27: =IFERROR(H27*J27," ") | L27: =IFERROR(IF(B27="TRAFO",K27,SUMIFS($L$11:$L$64,$A$11:$A$64,B27)+K27)," ")
... A64: 55 | D64: ='PROJ 01'!K57 -> 0 | E64: ='PROJ 01'!R57 -> 0 | F64: =D64+E64 -> 0 | G64: =SUMIF($B$11:$B$64,A64,$G$11:$G$64)+F64 -> 0 | H64: =((D64/2)+G64)*C64 -> 0 | J64: =IFERROR(VLOOKUP(I64,'BASE DE DADOS'!$A$4:$B$83,2,0)," ") | K64: =IFERROR(H64*J64," ") | L64: =IFERROR(IF(B64="TRAFO",K64,SUMIFS($L$11:$L$64,$A$11:$A$64,B64)+K64)," ")

Sheet MELHORADO
J1: TRECHO | K1: TOTAL | L1: MONO | M1: BI | N1: TRI | O1: TRI ESPECIAL | R1: TOTAL | S1: IP70W | T1: IP80W | U1: IP150W | V1: IP250W | W1: IP400W
A2: DEMANDA DIVERSIFICADA EM KVA | F2: LUMIN. | G2: QUANT | H2: DEMANDA | O2: QUANT | P2: CARGA
A3: TIPO DE LIGAÇÃO | C3: CLASSE "B" | F3: IP70W | G3: =SUM(S3:S57) -> 0 | H3: 0.07 | J3: TRAFO | K3: =SUM(L3:N3)*$C$5+P3 -> 75 | O3: 1 | P3: 75 | R3: =S3*$H$3+T3*$H$4+U3*$H$5+V3*$H$6+W3*$H$7 -> 0
A4: TOTAL DE CLIENTES | C4: =SUM(L3:O57) -> 1 | F4: IP80W | G4: =SUM(T3:T57) -> 0 | H4: 0.08 | J4: 2 | K4: =SUM(L4:N4)*$C$5+P4 -> 0 | R4: =S4*$H$3+T4*$H$4+U4*$H$5+V4*$H$6+W4*$H$7 -> 0
A5: DEMANDA UNITÁRIA | C5: 1.6 | F5: IP150W | G5: =SUM(U3:U57) -> 0 | H5: 0.15 | J5: 3 | K5: =SUM(L5:N5)*$C$5+P5 -> 0 | R5: =S5*$H$3+T5*$H$4+U5*$H$5+V5*$H$6+W5*$H$7 -> 0
F6: IP250W | G6: =SUM(V3:V57) -> 0 | H6: 0.25 | J6: 4 | K6: =SUM(L6:N6)*$C$5+P6 -> 0 | R6: =S6*$H$3+T6*$H$4+U6*$H$5+V6*$H$6+W6*$H$7 -> 0
F7: IP400W | G7: =SUM(W3:W57) -> 0 | H7: 0.4 | J7: 5 | K7: =SUM(L7:N7)*$C$5+P7 -> 0 | R7: =S7*$H$3+T7*$H$4+U7*$H$5+V7*$H$6+W7*$H$7 -> 0
J8: 6 | K8: =SUM(L8:N8)*$C$5+P8 -> 0 | R8: =S8*$H$3+T8*$H$4+U8*$H$5+V8*$H$6+W8*$H$7 -> 0
J9: 7 | K9: =SUM(L9:N9)*$C$5+P9 -> 0 | R9: =S9*$H$3+T9*$H$4+U9*$H$5+V9*$H$6+W9*$H$7 -> 0
J10: 8 | K10: =SUM(L10:N10)*$C$5+P10 -> 0 | R10: =S10*$H$3+T10*$H$4+U10*$H$5+V10*$H$6+W10*$H$7 -> 0
J11: 9 | K11: =SUM(L11:N11)*$C$5+P11 -> 0 | R11: =S11*$H$3+T11*$H$4+U11*$H$5+V11*$H$6+W11*$H$7 -> 0
J12: 10 | K12: =SUM(L12:N12)*$C$5+P12 -> 0 | R12: =S12*$H$3+T12*$H$4+U12*$H$5+V12*$H$6+W12*$H$7 -> 0
J13: 11 | K13: =SUM(L13:N13)*$C$5+P13 -> 0 | R13: =S13*$H$3+T13*$H$4+U13*$H$5+V13*$H$6+W13*$H$7 -> 0
J14: 12 | K14: =SUM(L14:N14)*$C$5+P14 -> 0 | R14: =S14*$H$3+T14*$H$4+U14*$H$5+V14*$H$6+W14*$H$7 -> 0
J15: 13 | K15: =SUM(L15:N15)*$C$5+P15 -> 0 | R15: =S15*$H$3+T15*$H$4+U15*$H$5+V15*$H$6+W15*$H$7 -> 0
J16: 14 | K16: =SUM(L16:N16)*$C$5+P16 -> 0 | R16: =S16*$H$3+T16*$H$4+U16*$H$5+V16*$H$6+W16*$H$7 -> 0
J17: 15 | K17: =SUM(L17:N17)*$C$5+P17 -> 0 | R17: =S17*$H$3+T17*$H$4+U17*$H$5+V17*$H$6+W17*$H$7 -> 0
J18: 16 | K18: =SUM(L18:N18)*$C$5+P18 -> 0 | R18: =S18*$H$3+T18*$H$4+U18*$H$5+V18*$H$6+W18*$H$7 -> 0
J19: 17 | K19: =SUM(L19:N19)*$C$5+P19 -> 0 | R19: =S19*$H$3+T19*$H$4+U19*$H$5+V19*$H$6+W19*$H$7 -> 0
... J57: 55 | K57: =SUM(L57:N57)*$C$5+P57 -> 0 | R57: =S57*$H$3+T57*$H$4+U57*$H$5+V57*$H$6+W57*$H$7 -> 0

Sheet CQT MELHORADO
A1: PROJETO | B1: A052750522 | G1: CARREGAMENTO TRANSFORMADOR
A3: SUBESTAÇÃO | B3: SANTA CLARA | D3: POTÊNCIA DO TRANSFORMADOR - kVA | F3: 75 | G3: =(F5)/F3 -> 1
A4: TAXA DE CRESCIMENTO ANUAL | B4: =VLOOKUP(B3,'BASE DE DADOS'!P:R,2,0) -> 0.035 | D4: PONTO ELÉTRICO DO TRANSFORMADOR | F4: C380653
A5: FATOR MULTIPLICATIVO 5 ANOS | B5: 1 | D5: DEMANDA TOTAL DO CIRCUITO DE BT - kVA | F5: =SUM(MELHORADO!K3:K57)+SUM(MELHORADO!R3:R57) -> 75
A7: TRECHOS | D7: CARGAS | I7: CONDUTOR | J7: QUEDA DE TENSÃO
A8: TRECHO | B8: TRECHO MONTANTE | C8: COMPRIMENTO | D8: DISTRIBUÍDA NO TRECHO | G8: ACUMULADA NO FINAL DO TRECHO | H8: TOTAL (C/2+D)*B | J8: UNITÁRIO | K8: NO TRECHO | L8: TOTAL
A9: A | C9: B - 100 | D9: C - kVA | G9: D - kVA | H9: E - kVA x B | I9: F - mm² | J9: G - % | K9: H - % | L9: I - %
D10: CLIENTES | E10: ILUMINAÇÃO PÚBLICA | F10: TOTAL DO TRECHO
A11: 2 | D11: =MELHORADO!K4 -> 0 | E11: =MELHORADO!R4 -> 0 | F11: =D11+E11 -> 0 | G11: =SUMIF($B$11:$B$64,A11,$G$11:$G$64)+F11 -> 0 | H11: =((D11/2)+G11)*C11 -> 0 | J11: =IFERROR(VLOOKUP(I11,'BASE DE DADOS'!$A$4:$B$83,2,0)," ") | K11: =IFERROR(H11*J11," ") | L11: =IFERROR(IF(B11="TRAFO",K11,SUMIFS($L$11:$L$64,$A$11:$A$64,B11)+K11)," ")
A12: 3 | D12: =MELHORADO!K5 -> 0 | E12: =MELHORADO!R5 -> 0 | F12: =D12+E12 -> 0 | G12: =SUMIF($B$11:$B$64,A12,$G$11:$G$64)+F12 -> 0 | H12: =((D12/2)+G12)*C12 -> 0 | J12: =IFERROR(VLOOKUP(I12,'BASE DE DADOS'!$A$4:$B$83,2,0)," ") | K12: =IFERROR(H12*J12," ") | L12: =IFERROR(IF(B12="TRAFO",K12,SUMIFS($L$11:$L$64,$A$11:$A$64,B12)+K12)," ")
A13: 4 | D13: =MELHORADO!K6 -> 0 | E13: =MELHORADO!R6 -> 0 | F13: =D13+E13 -> 0 | G13: =SUMIF($B$11:$B$64,A13,$G$11:$G$64)+F13 -> 0 | H13: =((D13/2)+G13)*C13 -> 0 | J13: =IFERROR(VLOOKUP(I13,'BASE DE DADOS'!$A$4:$B$83,2,0)," ") | K13: =IFERROR(H13*J13," ") | L13: =IFERROR(IF(B13="TRAFO",K13,SUMIFS($L$11:$L$64,$A$11:$A$64,B13)+K13)," ")
A14: 5 | D14: =MELHORADO!K7 -> 0 | E14: =MELHORADO!R7 -> 0 | F14: =D14+E14 -> 0 | G14: =SUMIF($B$11:$B$64,A14,$G$11:$G$64)+F14 -> 0 | H14: =((D14/2)+G14)*C14 -> 0 | J14: =IFERROR(VLOOKUP(I14,'BASE DE DADOS'!$A$4:$B$83,2,0)," ") | K14: =IFERROR(H14*J14," ") | L14: =IFERROR(IF(B14="TRAFO",K14,SUMIFS($L$11:$L$64,$A$11:$A$64,B14)+K14)," ")
A15: 6 | D15: =MELHORADO!K8 -> 0 | E15: =MELHORADO!R8 -> 0 | F15: =D15+E15 -> 0 | G15: =SUMIF($B$11:$B$64,A15,$G$11:$G$64)+F15 -> 0 | H15: =((D15/2)+G15)*C15 -> 0 | J15: =IFERROR(VLOOKUP(I15,'BASE DE DADOS'!$A$4:$B$83,2,0)," ") | K15: =IFERROR(H15*J15," ") | L15: =IFERROR(IF(B15="TRAFO",K15,SUMIFS($L$11:$L$64,$A$11:$A$64,B15)+K15)," ")
A16: 7 | D16: =MELHORADO!K9 -> 0 | E16: =MELHORADO!R9 -> 0 | F16: =D16+E16 -> 0 | G16: =SUMIF($B$11:$B$64,A16,$G$11:$G$64)+F16 -> 0 | H16: =((D16/2)+G16)*C16 -> 0 | J16: =IFERROR(VLOOKUP(I16,'BASE DE DADOS'!$A$4:$B$83,2,0)," ") | K16: =IFERROR(H16*J16," ") | L16: =IFERROR(IF(B16="TRAFO",K16,SUMIFS($L$11:$L$64,$A$11:$A$64,B16)+K16)," ")
A17: 8 | D17: =MELHORADO!K10 -> 0 | E17: =MELHORADO!R10 -> 0 | F17: =D17+E17 -> 0 | G17: =SUMIF($B$11:$B$64,A17,$G$11:$G$64)+F17 -> 0 | H17: =((D17/2)+G17)*C17 -> 0 | J17: =IFERROR(VLOOKUP(I17,'BASE DE DADOS'!$A$4:$B$83,2,0)," ") | K17: =IFERROR(H17*J17," ") | L17: =IFERROR(IF(B17="TRAFO",K17,SUMIFS($L$11:$L$64,$A$11:$A$64,B17)+K17)," ")
A18: 9 | D18: =MELHORADO!K11 -> 0 | E18: =MELHORADO!R11 -> 0 | F18: =D18+E18 -> 0 | G18: =SUMIF($B$11:$B$64,A18,$G$11:$G$64)+F18 -> 0 | H18: =((D18/2)+G18)*C18 -> 0 | J18: =IFERROR(VLOOKUP(I18,'BASE DE DADOS'!$A$4:$B$83,2,0)," ") | K18: =IFERROR(H18*J18," ") | L18: =IFERROR(IF(B18="TRAFO",K18,SUMIFS($L$11:$L$64,$A$11:$A$64,B18)+K18)," ")
A19: 10 | D19: =MELHORADO!K12 -> 0 | E19: =MELHORADO!R12 -> 0 | F19: =D19+E19 -> 0 | G19: =SUMIF($B$11:$B$64,A19,$G$11:$G$64)+F19 -> 0 | H19: =((D19/2)+G19)*C19 -> 0 | J19: =IFERROR(VLOOKUP(I19,'BASE DE DADOS'!$A$4:$B$83,2,0)," ") | K19: =IFERROR(H19*J19," ") | L19: =IFERROR(IF(B19="TRAFO",K19,SUMIFS($L$11:$L$64,$A$11:$A$64,B19)+K19)," ")
A20: 11 | D20: =MELHORADO!K13 -> 0 | E20: =MELHORADO!R13 -> 0 | F20: =D20+E20 -> 0 | G20: =SUMIF($B$11:$B$64,A20,$G$11:$G$64)+F20 -> 0 | H20: =((D20/2)+G20)*C20 -> 0 | J20: =IFERROR(VLOOKUP(I20,'BASE DE DADOS'!$A$4:$B$83,2,0)," ") | K20: =IFERROR(H20*J20," ") | L20: =IFERROR(IF(B20="TRAFO",K20,SUMIFS($L$11:$L$64,$A$11:$A$64,B20)+K20)," ")
A21: 12 | D21: =MELHORADO!K14 -> 0 | E21: =MELHORADO!R14 -> 0 | F21: =D21+E21 -> 0 | G21: =SUMIF($B$11:$B$64,A21,$G$11:$G$64)+F21 -> 0 | H21: =((D21/2)+G21)*C21 -> 0 | J21: =IFERROR(VLOOKUP(I21,'BASE DE DADOS'!$A$4:$B$83,2,0)," ") | K21: =IFERROR(H21*J21," ") | L21: =IFERROR(IF(B21="TRAFO",K21,SUMIFS($L$11:$L$64,$A$11:$A$64,B21)+K21)," ")
A22: 13 | D22: =MELHORADO!K15 -> 0 | E22: =MELHORADO!R15 -> 0 | F22: =D22+E22 -> 0 | G22: =SUMIF($B$11:$B$64,A22,$G$11:$G$64)+F22 -> 0 | H22: =((D22/2)+G22)*C22 -> 0 | J22: =IFERROR(VLOOKUP(I22,'BASE DE DADOS'!$A$4:$B$83,2,0)," ") | K22: =IFERROR(H22*J22," ") | L22: =IFERROR(IF(B22="TRAFO",K22,SUMIFS($L$11:$L$64,$A$11:$A$64,B22)+K22)," ")
... A64: 55 | D64: =MELHORADO!K57 -> 0 | E64: =MELHORADO!R57 -> 0 | F64: =D64+E64 -> 0 | G64: =SUMIF($B$11:$B$64,A64,$G$11:$G$64)+F64 -> 0 | H64: =((D64/2)+G64)*C64 -> 0 | J64: =IFERROR(VLOOKUP(I64,'BASE DE DADOS'!$A$4:$B$83,2,0)," ") | K64: =IFERROR(H64*J64," ") | L64: =IFERROR(IF(B64="TRAFO",K64,SUMIFS($L$11:$L$64,$A$11:$A$64,B64)+K64)," ")

Sheet BASE DE DADOS
A1: COEFICIENTES DE QUEDA DE TENSÃO - BAIXA TENSÃO - (%/kVA x 100m) - 220/127 V | D1: NÚMERO DE ANOS | E1: FATORES DE MULTIPLICAÇÃO DE DEMANDA | P1: SUBESTAÇÃO | Q1: TAXA DE CRESCIMENTO | R1: FATOR DE MULTIPLICAÇÃO DE DEMANDA | T1: TRECHOS
A2: CABO | B2: COEFICIENTES | E2: TAXA DE CRESCIMENTO ANUAL | P2: ABADIA | Q2: 0.02 | R2: 1.104 | T2: TRAFO
E3: 0.01 | F3: 0.02 | G3: 0.03 | H3: 0.04 | I3: 0.05 | J3: 0.06 | K3: 0.08 | L3: 0.1 | M3: 0.12 | N3: 0.15 | P3: ALCÂNTARA | Q3: 0.04 | R3: 1.217 | T3: 2
A4: 3x150+1x80 - Al - F.P 1 | B4: 0.0573 | D4: 5 | E4: 1.051 | F4: 1.104 | G4: 1.159 | H4: 1.217 | I4: 1.276 | J4: 1.338 | K4: 1.469 | L4: 1.611 | M4: 1.762 | N4: 2.011 | P4: ALMEIDA PEREIRA | Q4: 0.02 | R4: 1.104 | T4: 3
A5: 3x95+1x54,6 - Al - F.P 1 | B5: 0.0891 | P5: ANGRA | Q5: 0.03 | R5: 1.159 | T5: 4
A6: 3x50+1x54,6 - Al - F.P 1 | B6: 0.1784 | P6: ARARUAMA | Q6: 0.035 | R6: 1.217 | T6: 5
A7: 3x50+1x50 - Al - F.P 1 | B7: 0.1784 | P7: AREAL | Q7: 0.02 | R7: 1.104 | T7: 6
A8: 3x35+1x54,6 - Al - F.P 1 | B8: 0.2416 | P8: ARRAIAL DO CABO | Q8: 0.03 | R8: 1.159 | T8: 7
A9: 3x35+1x35 - Al - F.P 1 | B9: 0.23 | P9: ARSENAL | Q9: 0.04 | R9: 1.217 | T9: 8
A10: 3x35+1x50 - Al - F.P 1 | B10: 0.23 | P10: AUGUSTO VIEIRA | Q10: 0.04 | R10: 1.217 | T10: 9
A11: 3x70+1x70 - Al - F.P 1 | B11: 0.1175 | P11: BACAXÁ | Q11: 0.035 | R11: 1.217 | T11: 10
A12: 3x95+1x70 - Al - F.P 1 | B12: 0.085 | P12: BAIXA GRANDE | Q12: 0.035 | R12: 1.217 | T12: 11
A13: 3x95+1x50 - Al - F.P 1 | B13: 0.085 | P13: BARCELOS | Q13: 0.02 | R13: 1.104 | T13: 12
A14: 3x120+70 - Al - F.P 1 | B14: 0.0673 | P14: BARRA | Q14: 0.04 | R14: 1.217 | T14: 13
A15: 3x150+70 - Al - F.P 1 | B15: 0.0508 | P15: BARRA ALEGRE | Q15: 0.03 | R15: 1.159 | T15: 14
A16: 2x16+25 - Al - F.P 1 | B16: 0.7779 | P16: BARRACÃO DOS MENDES (ENERGISA) | Q16: 0.03 | R16: 1.159 | T16: 15
... A56: 3# 2/0 - Al - F.P 0,8 | B56: 0.1338 | P56: ITATIAIA | Q56: 0.04 | R56: 1.217 | T56: 55
A57: 3# 4/0 - Al - F.P 0,8 | B57: 0.1024 | P57: JACUACANGA | Q57: 0.03 | R57: 1.159
A58: 2# 4(4) - Al - F.P 0,8 | B58: 0.7039 | P58: LIBERDADE | Q58: 0.04 | R58: 1.217
A59: 2# 2(4) - Al - F.P 0,8 | B59: 0.5591 | P59: MACABU | Q59: 0.035 | R59: 1.217
A60: 2# 2(2) - Al - F.P 0,8 | B60: 0.4867 | P60: MACAÉ | Q60: 0.04 | R60: 1.217
A61: 2# 1/0(2) - Al - F.P 0,8 | B61: 0.3957 | P61: MAMBUCABA | Q61: 0.03 | R61: 1.159
A62: 2# 2/0(2) - Al - F.P 0,8 | B62: 0.363 | P62: MARIA PAULA | Q62: 0.04 | R62: 1.217
A63: 1# 4(4) - Al - F.P 0,8 | B63: 1.8771 | P63: MARICÁ | Q63: 0.04 | R63: 1.217
A64: 1# 2(2) - Al - F.P 0,8 | B64: 1.2978 | P64: MARTINS LAGE | Q64: 0.02 | R64: 1.104
A65: 1# 1/0 (2) - Al - F.P 0,8 | B65: 1.1158 | P65: MIRACEMA | Q65: 0.04 | R65: 1.217
A66: 1# 2/0 (2) - Al - F.P 0,8 | B66: 1.0504 | P66: MOMBAÇA | Q66: 0.03 | R66: 1.159
A67: 3# 25 - Cu - F.P 0,8 | B67: 0.2195 | P67: MURIQUI | Q67: 0.03 | R67: 1.159
A68: 3# 35 - Cu - F.P 0,8 | B68: 0.1608 | P68: N. S. D' AJUDA | Q68: 0.04 | R68: 1.217
... A83: CONC 2#10 (10) CU | B83: 0.74 | P83: PONTINHA | Q83: 0.05 | R83: 1.276
P84: PORTÃO DO ROSA | Q84: 0.04 | R84: 1.217
P85: PORTO DO AÇU | Q85: 0.035 | R85: 1.217
P86: PORTO DO CARRO | Q86: 0.04 | R86: 1.217
P87: PORTO REAL | Q87: 0.04 | R87: 1.217
P88: QUISSAMÃ | Q88: 0.025 | R88: 1.159
P89: RETIRO SAUDOSO | Q89: 0.04 | R89: 1.217
P90: RIO BONITO | Q90: 0.035 | R90: 1.217
P91: RIO DA CIDADE | Q91: 0.035 | R91: 1.217
P92: RIO DAS OSTRAS | Q92: 0.045 | R92: 1.276
P93: ROCHA LEÃO | Q93: 0.04 | R93: 1.217
...
